<?xml version="1.0" encoding="utf-8"?>
<!-- =================================================================================== -->
<!-- |    This document was autogenerated by xacro from four_wheel_bot.xacro           | -->
<!-- |    EDITING THIS FILE BY HAND IS NOT RECOMMENDED                                 | -->
<!-- =================================================================================== -->
<robot name="four_wheel_bot" xmlns:xacro="http://www.ros.org/wiki/xacro">
  <!-- Z dimension -->
  <!-- ==== Main code ==== -->
  <!-- Links -->
  <link name="base_link">
    <collision>
      <origin xyz="0.0 0.0 0.375"/>
      <geometry>
        <box size="0.5 0.7 0.75"/>
      </geometry>
    </collision>
    <visual>
      <origin xyz="0.0 0.0 0.375"/>
      <geometry>
        <box size="0.5 0.7 0.75"/>
      </geometry>
      <material name="red">
        <color rgba="1.0 0.0 0.0 1.0"/>
      </material>
    </visual>
  </link>
  <!-- Parameters -->
  <!-- @name: Name of the wheel link. Actual name will be "${name}_wheel" -->
  <!-- @parent: Name of parent link. Default value "base_link" -->
  <!-- @x, @y and @z: Position of the wheel origin -->
  <!-- @reflect: Reflection of positioning, -1 for right sided and 1 for left sided -->
  <!-- Link definitions -->
  <link name="fr_wheel">
    <visual>
      <origin xyz="0.0 0.0 -0.0625"/>
      <geometry>
        <cylinder length="0.125" radius="0.125"/>
      </geometry>
      <material name="red"/>
    </visual>
  </link>
  <!-- Joint definition -->
  <joint name="wheel_fr" type="continuous">
    <origin rpy="0.0 -1.57079632679 0.0" xyz="0.25 0.35 0"/>
    <parent link="base_link"/>
    <child link="fr_wheel"/>
    <axis xyz="0.0 0.0 1.0"/>
  </joint>
  <!-- Parameters -->
  <!-- @name: Name of the wheel link. Actual name will be "${name}_wheel" -->
  <!-- @parent: Name of parent link. Default value "base_link" -->
  <!-- @x, @y and @z: Position of the wheel origin -->
  <!-- @reflect: Reflection of positioning, -1 for right sided and 1 for left sided -->
  <!-- Link definitions -->
  <link name="fl_wheel">
    <visual>
      <origin xyz="0.0 0.0 0.0625"/>
      <geometry>
        <cylinder length="0.125" radius="0.125"/>
      </geometry>
      <material name="red"/>
    </visual>
  </link>
  <!-- Joint definition -->
  <joint name="wheel_fl" type="continuous">
    <origin rpy="0.0 -1.57079632679 0.0" xyz="-0.25 0.35 0"/>
    <parent link="base_link"/>
    <child link="fl_wheel"/>
    <axis xyz="0.0 0.0 1.0"/>
  </joint>
  <!-- Parameters -->
  <!-- @name: Name of the wheel link. Actual name will be "${name}_wheel" -->
  <!-- @parent: Name of parent link. Default value "base_link" -->
  <!-- @x, @y and @z: Position of the wheel origin -->
  <!-- @reflect: Reflection of positioning, -1 for right sided and 1 for left sided -->
  <!-- Link definitions -->
  <link name="br_wheel">
    <visual>
      <origin xyz="0.0 0.0 -0.0625"/>
      <geometry>
        <cylinder length="0.125" radius="0.125"/>
      </geometry>
      <material name="red"/>
    </visual>
  </link>
  <!-- Joint definition -->
  <joint name="wheel_br" type="continuous">
    <origin rpy="0.0 -1.57079632679 0.0" xyz="0.25 -0.35 0"/>
    <parent link="base_link"/>
    <child link="br_wheel"/>
    <axis xyz="0.0 0.0 1.0"/>
  </joint>
  <!-- Parameters -->
  <!-- @name: Name of the wheel link. Actual name will be "${name}_wheel" -->
  <!-- @parent: Name of parent link. Default value "base_link" -->
  <!-- @x, @y and @z: Position of the wheel origin -->
  <!-- @reflect: Reflection of positioning, -1 for right sided and 1 for left sided -->
  <!-- Link definitions -->
  <link name="bl_wheel">
    <visual>
      <origin xyz="0.0 0.0 0.0625"/>
      <geometry>
        <cylinder length="0.125" radius="0.125"/>
      </geometry>
      <material name="red"/>
    </visual>
  </link>
  <!-- Joint definition -->
  <joint name="wheel_bl" type="continuous">
    <origin rpy="0.0 -1.57079632679 0.0" xyz="-0.25 -0.35 0"/>
    <parent link="base_link"/>
    <child link="bl_wheel"/>
    <axis xyz="0.0 0.0 1.0"/>
  </joint>
</robot>

