<?xml version="1.0" encoding="utf-8"?>
<!-- =================================================================================== -->
<!-- |    This document was autogenerated by xacro from first_xacro.xacro              | -->
<!-- |    EDITING THIS FILE BY HAND IS NOT RECOMMENDED                                 | -->
<!-- =================================================================================== -->
<robot name="xacro_bot1" xmlns:xacro="http://www.ros.org/wiki/xacro">
  <!-- Base link -->
  <link name="base_link">
    <visual>
      <origin xyz="0 0 0.25"/>
      <geometry>
        <box size="0.5 0.5 0.5"/>
      </geometry>
    </visual>
  </link>
  <!-- Physical link -->
  <link name="l1_link">
    <visual>
      <origin xyz="0.0 0.0 0.3125"/>
      <geometry>
        <box size="0.2 0.2 0.625"/>
      </geometry>
    </visual>
    <material name="red">
      <color rgba="1.0 0.0 0.0 0.0"/>
    </material>
  </link>
  <!-- Joint between parent and link -->
  <joint name="l1_joint" type="revolute">
    <origin rpy="0.0 0.0 0.0" xyz="0 0 0.5"/>
    <parent link="base_link"/>
    <child link="l1_link"/>
    <axis xyz="0 1 0"/>
    <limit effort="30" lower="-3.14159265359" upper="3.14159265359" velocity="10"/>
  </joint>
  <!-- Physical link -->
  <link name="l2_link">
    <visual>
      <origin xyz="0.0 0.0 0.3125"/>
      <geometry>
        <box size="0.2 0.2 0.625"/>
      </geometry>
    </visual>
    <material name="red">
      <color rgba="1.0 0.0 0.0 0.0"/>
    </material>
  </link>
  <!-- Joint between parent and link -->
  <joint name="l2_joint" type="revolute">
    <origin xyz="0.0 0.0 0.625"/>
    <parent link="l1_link"/>
    <child link="l2_link"/>
    <axis xyz="1 0 0"/>
    <limit effort="30" lower="-3.14159265359" upper="3.14159265359" velocity="10"/>
  </joint>
  <!-- Physical link -->
  <link name="l3_link">
    <visual>
      <origin xyz="0.0 0.0 0.25"/>
      <geometry>
        <box size="0.2 0.2 0.5"/>
      </geometry>
    </visual>
    <material name="red">
      <color rgba="1.0 0.0 0.0 0.0"/>
    </material>
  </link>
  <!-- Joint between parent and link -->
  <joint name="l3_joint" type="revolute">
    <origin xyz="0.0 0.0 0.625"/>
    <parent link="l2_link"/>
    <child link="l3_link"/>
    <axis xyz="0 0 1"/>
    <limit effort="30" lower="-3.14159265359" upper="3.14159265359" velocity="10"/>
  </joint>
  <!-- Physical link -->
  <link name="l4_link">
    <visual>
      <origin xyz="0.0 0.0 0.5"/>
      <geometry>
        <box size="0.2 0.2 1"/>
      </geometry>
    </visual>
    <material name="red">
      <color rgba="1.0 0.0 0.0 0.0"/>
    </material>
  </link>
  <!-- Joint between parent and link -->
  <joint name="l4_joint" type="revolute">
    <origin xyz="0.0 0.0 0.5"/>
    <parent link="l3_link"/>
    <child link="l4_link"/>
    <axis xyz="1 0 0"/>
    <limit effort="30" lower="-3.14159265359" upper="3.14159265359" velocity="10"/>
  </joint>
  <!-- Physical link -->
  <link name="l5_link">
    <visual>
      <origin xyz="0.0 0.0 0.5"/>
      <geometry>
        <box size="0.2 0.2 1"/>
      </geometry>
    </visual>
    <material name="red">
      <color rgba="1.0 0.0 0.0 0.0"/>
    </material>
  </link>
  <!-- Joint between parent and link -->
  <joint name="l5_joint" type="revolute">
    <origin xyz="0.0 0.0 1"/>
    <parent link="l4_link"/>
    <child link="l5_link"/>
    <axis xyz="0 1 0"/>
    <limit effort="30" lower="-3.14159265359" upper="3.14159265359" velocity="10"/>
  </joint>
</robot>

