<?xml version="1.0" encoding="utf-8"?>
<!-- =================================================================================== -->
<!-- |    This document was autogenerated by xacro from four_wheel_bot.xacro           | -->
<!-- |    EDITING THIS FILE BY HAND IS NOT RECOMMENDED                                 | -->
<!-- =================================================================================== -->
<robot name="four_wheel_bot" xmlns:xacro="http://www.ros.org/wiki/xacro">
  <!-- Camera square side length -->
  <!-- For the robot -->
  <gazebo>
    <static>false</static>
    <plugin filename="libgazebo_ros_skid_steer_drive.so" name="skid_steer_drive_controller">
      <!-- Update rate -->
      <updateRate>100</updateRate>
      <!-- Wheel joint names from XACRO file -->
      <rightFrontJoint>wheel_fr</rightFrontJoint>
      <leftFrontJoint>wheel_fl</leftFrontJoint>
      <rightRearJoint>wheel_br</rightRearJoint>
      <leftRearJoint>wheel_bl</leftRearJoint>
      <!-- Wheel separation: Distance b/w front and rear (1.4 for us) -->
      <wheelSeparation>1.4</wheelSeparation>
      <!-- Wheel diameter: 0.5 here -->
      <wheelDiameter>0.5</wheelDiameter>
      <!-- Robot base link -->
      <robotBaseFrame>base_link</robotBaseFrame>
      <!-- Torque for the joints -->
      <torque>20</torque>
      <!-- Topic name for command velocities -->
      <commandTopic>cmd_vel</commandTopic>
    </plugin>
  </gazebo>
  <!-- For the link: base_link -->
  <gazebo reference="base_link">
    <material>Gazebo/Orange</material>
  </gazebo>
  <!-- For the link: fr_wheel (front right wheel) -->
  <gazebo reference="fr_wheel">
    <material>Gazebo/Black</material>
  </gazebo>
  <!-- For the link: br_wheel (back right wheel) -->
  <gazebo reference="br_wheel">
    <material>Gazebo/Black</material>
  </gazebo>
  <!-- For the link: fl_wheel (front left wheel) -->
  <gazebo reference="fl_wheel">
    <material>Gazebo/Black</material>
  </gazebo>
  <!-- For the link: bl_wheel (back left wheel) -->
  <gazebo reference="bl_wheel">
    <material>Gazebo/Black</material>
  </gazebo>
  <!-- For the link: camera_link -->
  <gazebo reference="camera_link">
    <!-- Material -->
    <material>Gazebo/Blue</material>
    <!-- Camera sensor -->
    <sensor name="camera1" type="camera">
      <!-- Frame rate -->
      <update_rate>30.0</update_rate>
      <!-- Camera properties -->
      <camera name="head">
        <!-- Horizontal field of view -->
        <horizontal_fov>1.3962634</horizontal_fov>
        <!-- Image properties -->
        <image>
          <width>800</width>
          <height>800</height>
          <format>R8G8B8</format>
        </image>
        <!-- Clip images to distance -->
        <clip>
          <near>0.02</near>
          <far>300</far>
        </clip>
        <!-- Gaussian noise -->
        <noise>
          <type>gaussian</type>
          <mean>0.00</mean>
          <stddev>0.007</stddev>
        </noise>
      </camera>
      <!-- Camera plugin -->
      <plugin filename="libgazebo_ros_camera.so" name="camera_controller">
        <alwaysOn>true</alwaysOn>
        <updateRate>0.0</updateRate>
        <!-- Topic names -->
        <imageTopicName>/four_wheel_bot/camera/image_raw</imageTopicName>
        <cameraInfoTopicName>/four_wheel_bot/camera/camera_info</cameraInfoTopicName>
        <!-- Camera frame -->
        <frameName>camera_link</frameName>
        <hackBaseline>0.07</hackBaseline>
        <distortionK1>0.0</distortionK1>
        <distortionK2>0.0</distortionK2>
        <distortionK3>0.0</distortionK3>
        <distortionT1>0.0</distortionT1>
        <distortionT2>0.0</distortionT2>
      </plugin>
    </sensor>
  </gazebo>
  <!-- ==== Main code ==== -->
  <!-- === Links === -->
  <!-- Base link -->
  <link name="base_link">
    <collision>
      <origin xyz="0.0 0.0 0.25"/>
      <geometry>
        <box size="1.4 1 0.5"/>
      </geometry>
    </collision>
    <visual>
      <origin xyz="0.0 0.0 0.25"/>
      <geometry>
        <box size="1.4 1 0.5"/>
      </geometry>
      <material name="red">
        <color rgba="1.0 0.0 0.0 1.0"/>
      </material>
    </visual>
    <inertial>
      <origin rpy="0.0 0.0 0.0" xyz="0.0 0.0 0.0"/>
      <mass value="2.0"/>
      <inertia ixx="1.0" ixy="0.0" ixz="0.0" iyy="1.0" iyz="0.0" izz="1.0"/>
    </inertial>
  </link>
  <!-- Parameters -->
  <!-- @name: Name of the wheel link. Actual name will be "${name}_wheel. Joint name will be wheel_${name}" -->
  <!-- @parent: Name of parent link. Default value "base_link" -->
  <!-- @x, @y and @z: Position of the wheel origin -->
  <!-- @reflect: Reflection of positioning, -1 for right sided and 1 for left sided -->
  <!-- Link definitions -->
  <link name="fr_wheel">
    <collision>
      <origin xyz="0.0 0.0 -0.125"/>
      <geometry>
        <cylinder length="0.25" radius="0.25"/>
      </geometry>
    </collision>
    <visual>
      <origin xyz="0.0 0.0 -0.125"/>
      <geometry>
        <cylinder length="0.25" radius="0.25"/>
      </geometry>
      <material name="red"/>
    </visual>
    <inertial>
      <origin rpy="0.0 0.0 0.0" xyz="0.0 0.0 0.0"/>
      <mass value="0.5"/>
      <inertia ixx="1.0" ixy="0.0" ixz="0.0" iyy="1.0" iyz="0.0" izz="1.0"/>
    </inertial>
  </link>
  <!-- Joint definition -->
  <joint name="wheel_fr" type="continuous">
    <origin rpy="-1.57079632679 0.0 0.0" xyz="0.7 0.5 0"/>
    <parent link="base_link"/>
    <child link="fr_wheel"/>
    <axis xyz="0.0 0.0 1.0"/>
  </joint>
  <!-- Parameters -->
  <!-- @name: Name of the wheel link. Actual name will be "${name}_wheel. Joint name will be wheel_${name}" -->
  <!-- @parent: Name of parent link. Default value "base_link" -->
  <!-- @x, @y and @z: Position of the wheel origin -->
  <!-- @reflect: Reflection of positioning, -1 for right sided and 1 for left sided -->
  <!-- Link definitions -->
  <link name="fl_wheel">
    <collision>
      <origin xyz="0.0 0.0 0.125"/>
      <geometry>
        <cylinder length="0.25" radius="0.25"/>
      </geometry>
    </collision>
    <visual>
      <origin xyz="0.0 0.0 0.125"/>
      <geometry>
        <cylinder length="0.25" radius="0.25"/>
      </geometry>
      <material name="red"/>
    </visual>
    <inertial>
      <origin rpy="0.0 0.0 0.0" xyz="0.0 0.0 0.0"/>
      <mass value="0.5"/>
      <inertia ixx="1.0" ixy="0.0" ixz="0.0" iyy="1.0" iyz="0.0" izz="1.0"/>
    </inertial>
  </link>
  <!-- Joint definition -->
  <joint name="wheel_fl" type="continuous">
    <origin rpy="-1.57079632679 0.0 0.0" xyz="-0.7 0.5 0"/>
    <parent link="base_link"/>
    <child link="fl_wheel"/>
    <axis xyz="0.0 0.0 1.0"/>
  </joint>
  <!-- Parameters -->
  <!-- @name: Name of the wheel link. Actual name will be "${name}_wheel. Joint name will be wheel_${name}" -->
  <!-- @parent: Name of parent link. Default value "base_link" -->
  <!-- @x, @y and @z: Position of the wheel origin -->
  <!-- @reflect: Reflection of positioning, -1 for right sided and 1 for left sided -->
  <!-- Link definitions -->
  <link name="br_wheel">
    <collision>
      <origin xyz="0.0 0.0 -0.125"/>
      <geometry>
        <cylinder length="0.25" radius="0.25"/>
      </geometry>
    </collision>
    <visual>
      <origin xyz="0.0 0.0 -0.125"/>
      <geometry>
        <cylinder length="0.25" radius="0.25"/>
      </geometry>
      <material name="red"/>
    </visual>
    <inertial>
      <origin rpy="0.0 0.0 0.0" xyz="0.0 0.0 0.0"/>
      <mass value="0.5"/>
      <inertia ixx="1.0" ixy="0.0" ixz="0.0" iyy="1.0" iyz="0.0" izz="1.0"/>
    </inertial>
  </link>
  <!-- Joint definition -->
  <joint name="wheel_br" type="continuous">
    <origin rpy="-1.57079632679 0.0 0.0" xyz="0.7 -0.5 0"/>
    <parent link="base_link"/>
    <child link="br_wheel"/>
    <axis xyz="0.0 0.0 1.0"/>
  </joint>
  <!-- Parameters -->
  <!-- @name: Name of the wheel link. Actual name will be "${name}_wheel. Joint name will be wheel_${name}" -->
  <!-- @parent: Name of parent link. Default value "base_link" -->
  <!-- @x, @y and @z: Position of the wheel origin -->
  <!-- @reflect: Reflection of positioning, -1 for right sided and 1 for left sided -->
  <!-- Link definitions -->
  <link name="bl_wheel">
    <collision>
      <origin xyz="0.0 0.0 0.125"/>
      <geometry>
        <cylinder length="0.25" radius="0.25"/>
      </geometry>
    </collision>
    <visual>
      <origin xyz="0.0 0.0 0.125"/>
      <geometry>
        <cylinder length="0.25" radius="0.25"/>
      </geometry>
      <material name="red"/>
    </visual>
    <inertial>
      <origin rpy="0.0 0.0 0.0" xyz="0.0 0.0 0.0"/>
      <mass value="0.5"/>
      <inertia ixx="1.0" ixy="0.0" ixz="0.0" iyy="1.0" iyz="0.0" izz="1.0"/>
    </inertial>
  </link>
  <!-- Joint definition -->
  <joint name="wheel_bl" type="continuous">
    <origin rpy="-1.57079632679 0.0 0.0" xyz="-0.7 -0.5 0"/>
    <parent link="base_link"/>
    <child link="bl_wheel"/>
    <axis xyz="0.0 0.0 1.0"/>
  </joint>
  <!-- Camera sensor joint -->
  <joint name="joint_name" type="fixed">
    <parent link="base_link"/>
    <child link="camera_link"/>
    <origin rpy="0.0 0.0 0.0" xyz="0.6375 0.0 0.5"/>
  </joint>
  <!-- Camera sensor link -->
  <link name="camera_link">
    <collision>
      <origin xyz="0.0 0.0 0.0625"/>
      <geometry>
        <box size="0.125 0.125 0.125"/>
      </geometry>
    </collision>
    <visual>
      <origin xyz="0.0 0.0 0.0625"/>
      <geometry>
        <box size="0.125 0.125 0.125"/>
      </geometry>
      <material name="red"/>
    </visual>
    <inertial>
      <origin rpy="0.0 0.0 0.0" xyz="0.0 0.0 0.0"/>
      <mass value="0.1"/>
      <inertia ixx="1.0" ixy="0.0" ixz="0.0" iyy="1.0" iyz="0.0" izz="1.0"/>
    </inertial>
  </link>
</robot>

